Workbook
Name ZODYNAS: [1]Zodynas!$A$2:$B$239

Sheet U4B
A2: ctr shift + iterpti eilute | I2: 1. Lentelės sudarymo ir formatavimo pratimai
A3: formtavimo kopijavimas
I4: UAB "VAISIAI IR DARŽUVĖS" 2019 m. II-o ketvirčio pardavimai
I6: Kainininkas 1 | L6: Kainininkas 2
A8: UAB "VAISIAI IR DARŽUVĖS" 2019 m. II-o ketvirčio pardavimai | I8: Vaisių ir uogų kainos | L8: Daržovių kainos
D10: Kiekis, kg. | I10: Pavadinimas | J10: Kaina, Eur/kg | L10: Pavadinimas | M10: Kaina, Eur/kg
A11: Prekės kategorija | B11: Pavadinimas | C11: Kainos | D11: Vasaris | E11: Kovas | F11: Balandis | G11: Suma, Eur | I11: Apelsinai | J11: 0.9 | L11: Agurkai | M11: 1.5
A12: Vaisiai ir uogos | B12: Obuoliai | C12: 1.8 | D12: 230 | E12: 260 | F12: 248 | G12: =SUM(C12:F12) -> 739.8 | I12: Bananai | J12: 0.9 | L12: Bulvės | M12: 1
A13: Vaisiai ir uogos | B13: Kriaušės | C13: 0.99 | D13: 420 | E13: 405 | F13: 410 | G13: =SUM(C13:F13) -> 1235.99 | I13: Citrinos | J13: 1.5 | L13: Kopūstai | M13: 0.69
A14: Vaisiai ir uogos | B14: Slyvos | C14: 2.5 | D14: 180 | E14: 150 | F14: 165 | G14: =SUM(C14:F14) -> 497.5 | I14: Kiviai | J14: 1.99 | L14: Pomidorai | M14: 1.89
A15: Vaisiai ir uogos | B15: Vynuogės | C15: 3.5 | D15: 50 | E15: 56 | F15: 52 | G15: =SUM(C15:F15) -> 161.5 | I15: Kriaušės | J15: 0.99 | L15: Porai | M15: 2.8
A16: Vaisiai ir uogos | B16: Bananai | C16: 0.9 | D16: 150 | E16: 175 | F16: 164 | G16: =SUM(C16:F16) -> 489.9 | I16: Melionai | J16: 1.55 | L16: Raudonieji burokėliai | M16: 0.5
A17: Vaisiai ir uogos | B17: Citrinos | C17: 1.5 | D17: 30 | E17: 21 | F17: 27 | G17: =SUM(C17:F17) -> 79.5 | I17: Obuoliai | J17: 1.8 | L17: Svogūnai | M17: 1.3
A18: Vaisiai ir uogos | B18: Apelsinai | C18: 0.9 | D18: 120 | E18: 99 | F18: 110 | G18: =SUM(C18:F18) -> 329.9 | I18: Slyvos | J18: 2.5
A19: Vaisiai ir uogos | B19: Kiviai | C19: 1.99 | D19: 20 | E19: 35 | F19: 28 | G19: =SUM(C19:F19) -> 84.99 | I19: Vynuogės | J19: 3.5
A20: Vaisiai ir uogos | B20: Melionai | C20: 1.55 | D20: 45 | E20: 75 | F20: 63 | G20: =SUM(C20:F20) -> 184.55
A21: Vaisiai ir uogos suma: | C21: =SUM(C12:C20) -> 15.63 | D21: =SUM(D12:D20) -> 1245 | E21: =SUM(E12:E20) -> 1276 | F21: =SUM(F12:F20) -> 1267 | G21: =SUM(C21:F21) -> 3803.63
A22: Daržovės | B22: Bulvės | C22: 1 | D22: 450 | E22: 436 | F22: 452 | G22: =SUM(C22:F22) -> 1339
A23: Daržovės | B23: Kopūstai | C23: 0.69 | D23: 355 | E23: 305 | F23: 321 | G23: =SUM(C23:F23) -> 981.69
A24: Daržovės | B24: Raudonieji burokėliai | C24: 0.5 | D24: 80 | E24: 76 | F24: 75 | G24: =SUM(C24:F24) -> 231.5
A25: Daržovės | B25: Porai | C25: 2.8 | D25: 58 | E25: 63 | F25: 59 | G25: =SUM(C25:F25) -> 182.8
A26: Daržovės | B26: Svogūnai | C26: 1.3 | D26: 123 | E26: 152 | F26: 139 | G26: =SUM(C26:F26) -> 415.3
A27: Daržovės | B27: Agurkai | C27: 1.5 | D27: 86 | E27: 96 | F27: 95 | G27: =SUM(C27:F27) -> 278.5
A28: Daržovės | B28: Pomidorai | C28: 1.89 | D28: 113 | E28: 105 | F28: 120 | G28: =SUM(C28:F28) -> 339.89
A29: Daržovės suma: | C29: =SUM(C22:C28) -> 9.68 | D29: =SUM(D22:D28) -> 1265 | E29: =SUM(E22:E28) -> 1233 | F29: =SUM(F22:F28) -> 1261 | G29: =SUM(C29:F29) -> 3768.68
A30: Viso: | C30: =SUM(C21,C29) -> 25.31 | D30: =SUM(D21,D29) -> 2510 | E30: =SUM(E21,E29) -> 2509 | F30: =SUM(F21,F29) -> 2528 | G30: =SUM(C30:F30) -> 7572.31
I31: 2. FORMAT PAINTER pagalba perkelkite lentelės formatą į naują ataskaitą
I33: Sena ataskaita
J35: Prad. likutis | K35: Priimta | L35: Atiduota | M35: Gal. likutis
I36: Obuoliai | J36: 15 | K36: 150 | L36: 120 | M36: =+J36+K36-L36 -> 45
I37: Kriaušės | J37: 5 | K37: 100 | L37: 95 | M37: =+J37+K37-L37 -> 10
I38: Slyvos | J38: 12 | K38: 45 | L38: 50 | M38: =+J38+K38-L38 -> 7
I39: Viso: | J39: =SUM(J36:J38) -> 32 | K39: =SUM(K36:K38) -> 295 | L39: =SUM(L36:L38) -> 265 | M39: =SUM(M36:M38) -> 62
A42: Nauja ataskaita | I42: Nauja ataskaita
B44: Prad. likutis | C44: Priimta | D44: Atiduota | E44: Gal. likutis | J44: Prad. likutis | K44: Priimta | L44: Atiduota | M44: Gal. likutis
A45: Obuoliai | B45: 45 | C45: 120 | D45: 145 | E45: 20 | I45: Obuoliai | J45: =+M36 -> 45 | K45: 120 | L45: 145 | M45: =+J45+K45-L45 -> 20
A46: Kriaušės | B46: 10 | C46: 95 | D46: 100 | E46: 5 | I46: Kriaušės | J46: =+M37 -> 10 | K46: 95 | L46: 100 | M46: =+J46+K46-L46 -> 5
A47: Slyvos | B47: 7 | C47: 50 | D47: 45 | E47: 12 | I47: Slyvos | J47: =+M38 -> 7 | K47: 50 | L47: 45 | M47: =+J47+K47-L47 -> 12
A48: Viso: | B48: 62 | C48: 265 | D48: 290 | E48: 37 | I48: Viso: | J48: =SUM(J45:J47) -> 62 | K48: =SUM(K45:K47) -> 265 | L48: =SUM(L45:L47) -> 290 | M48: =+J48+K48-L48 -> 37

Sheet U4C
B1: U4C | C1: Aritmetiniai veiksmai (formulės) ir pagrindinės funkcijos;
B4: UAB VAISIAI IR DARŽUVĖS pardavimai
B5: ,
B7: Prekės kategorija | C7: Pavadinimas | D7: Kainos | E7: Kiekis, kg. | H7: Viso, kg | I7: Suma, Eur
E8: vasaris | F8: kovas | G8: balandis
B9: Vaisiai ir uogos | C9: Obuoliai | D9: 0.9 | E9: 250 | F9: 350 | G9: 410 | H9: =SUM(D9:G9) -> 1010.9 | I9: =D9*H9 -> 909.81
C10: Kriaušės | D10: 1.2 | G10: 410 | H10: =SUM(D10:G10) -> 411.2 | I10: =D10*H10 -> 493.44 | K10: SUM | L10: =SUM(D9:D17) -> 15.93
C11: Slyvos | D11: 1.5 | E11: 180 | F11: 150 | G11: 165 | H11: =SUM(D11:G11) -> 496.5 | I11: =D11*H11 -> 744.75 | K11: AVERAGE | L11: =AVERAGE(D9:D17) -> 1.77
C12: Vynuogės | D12: 1.99 | E12: 50 | F12: 56 | G12: 52 | H12: =SUM(D12:G12) -> 159.99 | I12: =D12*H12 -> 318.3801 | K12: COUNT | L12: =COUNT(E9:E17) -> 7 | M12: skaiciuoja visus skaiciais uzpildytus langelius
C13: Bananai | D13: 0.99 | E13: 150 | F13: 175 | G13: 164 | H13: =SUM(D13:G13) -> 489.99 | I13: =D13*H13 -> 485.0901 | K13: COUNTA | L13: =COUNTA(E9:E17) -> 7
C14: Citrinos | D14: 1.55 | E14: 30 | F14: 21 | G14: 27 | H14: =SUM(D14:G14) -> 79.55 | I14: =D14*H14 -> 123.3025 | K14: COUNTBLANK | L14: =COUNTBLANK(G9:G17) -> 1 | M14: suskaiciavo tuscius langelius
C15: Apelsinai | D15: 1.8 | E15: 120 | F15: 99 | G15: 110 | H15: =SUM(D15:G15) -> 330.8 | I15: =D15*H15 -> 595.44 | K15: MAX | L15: =MAX(D9:D17) -> 3.5
C16: Kiviai | D16: 2.5 | H16: =SUM(D16:G16) -> 2.5 | I16: =D16*H16 -> 6.25 | K16: MIN | L16: =MIN(D9:D17) -> 0.9
C17: Melionai | D17: 3.5 | E17: 45 | F17: 75 | G17: 63 | H17: =SUM(D17:G17) -> 186.5 | I17: =D17*H17 -> 652.75 | K17: LARGE | L17: =LARGE(D9:D17,1) -> 3.5 | M17: pirma pagal dydi kaina
B18: Vaisiai ir uogos viso: | D18: =SUM(D9:D17) -> 15.93 | E18: =SUM(E9:E17) -> 825 | F18: =SUM(F9:F17) -> 926 | G18: =SUM(G9:G17) -> 1401 | H18: =SUM(H9:H17) -> 3167.93 | I18: =D18*H18 -> 50465.125 | K18: SMALL | L18: =SMALL(D9:D17,2) -> 0.99 | M18: antra pagal mazuma kaina
B19: Daržovės | C19: Bulvės | D19: 1.5 | E19: 450 | F19: 436 | H19: =SUM(D19:G19) -> 887.5 | I19: =D19*H19 -> 1331.25
C20: Kopūstai | D20: 1 | E20: 355 | F20: 305 | G20: 321 | H20: =SUM(D20:G20) -> 982 | I20: =D20*H20 -> 982
C21: Raudonieji burokėliai | D21: 0.69 | F21: 76 | G21: 75 | H21: =SUM(D21:G21) -> 151.69 | I21: =D21*H21 -> 104.6661
C22: Porai | D22: 1.89 | E22: 58 | F22: 63 | G22: 59 | H22: =SUM(D22:G22) -> 181.89 | I22: =D22*H22 -> 343.7721
C23: Svogūnai | D23: 2.8 | E23: 123 | F23: 152 | G23: 139 | H23: =SUM(D23:G23) -> 416.8 | I23: =D23*H23 -> 1167.04
C24: Agurkai | D24: 0.5 | E24: 86 | F24: 96 | G24: 95 | H24: =SUM(D24:G24) -> 277.5 | I24: =D24*H24 -> 138.75
C25: Pomidorai | D25: 1.3 | E25: 113 | F25: 105 | G25: 120 | H25: =SUM(D25:G25) -> 339.3 | I25: =D25*H25 -> 441.09
B26: Daržovės viso: | D26: =SUM(D19:D25) -> 9.68 | E26: =SUM(E19:E25) -> 1185 | F26: =SUM(F19:F25) -> 1233 | G26: =SUM(G19:G25) -> 809 | H26: =SUM(H19:H25) -> 3236.68 | I26: =D26*H26 -> 31331.062
B27: Iš viso: | D27: =SUM(D26,D18) -> 25.61 | E27: =SUM(E26,E18) -> 2010 | F27: =SUM(F26,F18) -> 2159 | G27: =SUM(G26,G18) -> 2210 | H27: =SUM(H26,H18) -> 6404.61 | I27: =D27*H27 -> 164022.06
B29: Apvalinimas. Reikia vaisių ir daržovių kainas padidinti 15% ir suapvalinti įprasuoju būdu iki cento.
C31: Pavadinimas | D31: Kainos | E31: Didinimo % | F31: Naujos kainos
C33: Obuoliai | D33: 0.9 | E33: 0.15 | F33: =ROUND(D33+(D33*E33), 3) -> 1.035 | H33: ROUND
C34: Kriaušės | D34: 1.2 | E34: 0.15 | F34: =ROUND(D34+(D34*E34), 3) -> 1.38 | H34: ROUNDUP | I34: I DIDZIAJA PUSE
C35: Slyvos | D35: 1.5 | E35: 0.15 | F35: =ROUND(D35+(D35*E35), 3) -> 1.725 | H35: ROUNDDOWN | I35: I MAZAJA PUSE APVALINIMAS | L35: ROUNDUP | M35: ROUNDDOWN
C36: Vynogės | D36: 1.99 | E36: 0.15 | F36: =ROUND(D36+(D36*E36), 3) -> 2.289 | L36: =ROUNDUP(F33,2) -> 1.04 | M36: =ROUNDDOWN(F33,2) -> 1.03
C37: Bananai | D37: 0.99 | E37: 0.15 | F37: =ROUND(D37+(D37*E37), 3) -> 1.139 | L37: =ROUNDUP(F34,2) -> 1.38 | M37: =ROUNDDOWN(F34,2) -> 1.38
C38: Citrinos | D38: 1.55 | E38: 0.15 | F38: =ROUND(D38+(D38*E38), 3) -> 1.783 | L38: =ROUNDUP(F35,2) -> 1.73 | M38: =ROUNDDOWN(F35,2) -> 1.72
C39: Apelsinai | D39: 1.8 | E39: 0.15 | F39: =ROUND(D39+(D39*E39), 3) -> 2.07 | L39: =ROUNDUP(F36,2) -> 2.29 | M39: =ROUNDDOWN(F36,2) -> 2.28
C40: Kiviai | D40: 2.5 | E40: 0.15 | F40: =ROUND(D40+(D40*E40), 3) -> 2.875 | L40: =ROUNDUP(F37,2) -> 1.14 | M40: =ROUNDDOWN(F37,2) -> 1.13
C41: Melionai | D41: 3.5 | E41: 0.15 | F41: =ROUND(D41+(D41*E41), 3) -> 4.025 | L41: =ROUNDUP(F38,2) -> 1.79 | M41: =ROUNDDOWN(F38,2) -> 1.78
C42: Bulvės | D42: 1.5 | E42: 0.15 | F42: =ROUND(D42+(D42*E42), 3) -> 1.725 | L42: =ROUNDUP(F39,2) -> 2.07 | M42: =ROUNDDOWN(F39,2) -> 2.07
C43: Kopūstai | D43: 1 | E43: 0.15 | F43: =ROUND(D43+(D43*E43), 3) -> 1.15 | L43: =ROUNDUP(F40,2) -> 2.88 | M43: =ROUNDDOWN(F40,2) -> 2.87
C44: Raudonieji burokėliai | D44: 0.69 | E44: 0.15 | F44: =ROUND(D44+(D44*E44), 3) -> 0.794 | L44: =ROUNDUP(F41,2) -> 4.03 | M44: =ROUNDDOWN(F41,2) -> 4.02
C45: Porai | D45: 1.89 | E45: 0.15 | F45: =ROUND(D45+(D45*E45), 3) -> 2.174 | L45: =ROUNDUP(F42,2) -> 1.73 | M45: =ROUNDDOWN(F42,2) -> 1.72
C46: Svogūnai | D46: 2.8 | E46: 0.15 | F46: =ROUND(D46+(D46*E46), 3) -> 3.22 | L46: =ROUNDUP(F43,2) -> 1.15 | M46: =ROUNDDOWN(F43,2) -> 1.15
...

Sheet U5
B1: U5 | C1: Formulių kopijavimas, langelių formatai, koordinatės (santykinės, absoliučios, mišrios)
B3: 1. | C3: =("Nukopijuokite formules iš langelių H"&ROW(H11)&" ir I"&ROW(I11)&" žemyn visiems vaisiams ir uogoms. Išlaikykite buvusį langelių formatą") -> Nukopijuokite formules iš langelių H11 ir I11 žemyn visiems vaisiams ir uogoms. Išlaikykite buvusį langelių formatą
B4: 2. | C4: =("Užrašykite sumavimo funkciją (SUM) langelyje E"&ROW(E20)&" ir ją nukopijuokite visuose kituose lentelės stulpeliuose. Išlaikykite buvusį langelių formatą") -> Užrašykite sumavimo funkciją (SUM) langelyje E20 ir ją nukopijuokite visuose kituose lentelės stulpeliuose. Išlaikykite buvusį langelių formatą
B5: 3. | C5: =("Užrašykite sumavimo funkcijas langelių H"&ROW(H20)&" ir I"&ROW(I20)&" (SUM)") -> Užrašykite sumavimo funkcijas langelių H20 ir I20 (SUM)
B6: 4. | C6: =("Užrašykite sandaugų sumavimo funkciją SUMPRODUCT (daugindami kainų ir susumuotų kiekių stulpelius) langelyje I"&ROW(I22)&". Išlaikykite buvusį langelių formatą") -> Užrašykite sandaugų sumavimo funkciją SUMPRODUCT (daugindami kainų ir susumuotų kiekių stulpelius) langelyje I22. Išlaikykite buvusį langelių formatą
B8: Prekės kategorija | C8: Pavadinimas | D8: Kainos | E8: Kiekis, kg | H8: Iš viso, kg | I8: Suma, Eur
E10: vasaris | F10: kovas | G10: balandis
B11: Vaisiai ir uogos | C11: Obuoliai | D11: 0.9 | E11: 250 | F11: 350 | G11: 410 | H11: =SUM(D11:G11) -> 1010.9 | I11: =D11*H11 -> 909.81 | J11: 1
C12: Kriaušės | D12: 1.2 | G12: 410 | H12: =SUM(D12:G12) -> 411.2 | I12: =D12*H12 -> 493.44 | J12: 1
C13: Slyvos | D13: 1.5 | E13: 180 | F13: 150 | G13: 165 | H13: =SUM(D13:G13) -> 496.5 | I13: =D13*H13 -> 744.75 | J13: 1
C14: Vynuogės | D14: 1.99 | E14: 50 | F14: 56 | G14: 52 | H14: =SUM(D14:G14) -> 159.99 | I14: =D14*H14 -> 318.3801 | J14: 0
C15: Bananai | D15: 0.99 | E15: 150 | F15: 175 | G15: 164 | H15: =SUM(D15:G15) -> 489.99 | I15: =D15*H15 -> 485.0901 | J15: 1
C16: Citrinos | D16: 1.55 | E16: 30 | F16: 21 | G16: 27 | H16: =SUM(D16:G16) -> 79.55 | I16: =D16*H16 -> 123.3025 | J16: 1
C17: Apelsinai | D17: 1.8 | E17: 120 | F17: 99 | G17: 110 | H17: =SUM(D17:G17) -> 330.8 | I17: =D17*H17 -> 595.44 | J17: 0
C18: Kiviai | D18: 2.5 | H18: =SUM(D18:G18) -> 2.5 | I18: =D18*H18 -> 6.25 | J18: 1
C19: Melionai | D19: 3.5 | E19: 45 | F19: 75 | G19: 63 | H19: =SUM(D19:G19) -> 186.5 | I19: =D19*H19 -> 652.75 | J19: 1
B20: Vaisiai ir uogos iš viso: | E20: =SUM(E11:E19) -> 825 | F20: =SUM(F11:F19) -> 926 | G20: =SUM(G11:G19) -> 1401 | H20: =SUM(E20:G20) -> 3152 | I20: =SUM(I11:I19) -> 4329.2127
G22: SUMPRODUCT->> | I22: =SUMPRODUCT(D11:D19,H11:H19,J11:J19) -> 3415.3926
B24: 5. | C24: =("Įrašykite formulę į langelį J"&ROW(J34)&" ir nukopijuokite ją į dešinę per du langelius. Išlaikykite buvusį langelių formatą. Gausime neteisingas formulės kopijas. Jas pataisyti galėsime pakeitę nuorodos tipą (6 užd.)") -> Įrašykite formulę į langelį J34 ir nukopijuokite ją į dešinę per du langelius. Išlaikykite buvusį langelių formatą. Gausime neteisingas formulės kopijas. Jas pataisyti galėsime pakeitę nuorodos tipą (6 užd.)
B26: 6. | C26: =("Pakoreguokite formulę langelyje J"&ROW(J34)&" užfiksuodami reikiamus nuorodų elementus $ ženklu ir nukopijuokite ją į likusius vaisių ir daržovių langelius. Išlaikykite buvusį langelių formatą") -> Pakoreguokite formulę langelyje J34 užfiksuodami reikiamus nuorodų elementus $ ženklu ir nukopijuokite ją į likusius vaisių ir daržovių langelius. Išlaikykite buvusį langelių formatą
B28: 7. | C28: =("Parašykite formulę komisiniams skaičiuoti langelyje M"&ROW(M34)&", užfiksuokite reikiamus nuorodų elementus $ ženklu ir nukopijuokite ją į likusius vaisių ir daržovių langelius. Išlaikykite buvusį langelių formatą. Įrašykite likusias galutinių sumų formules. Išlaikykite buvusį langelių formatą") -> Parašykite formulę komisiniams skaičiuoti langelyje M34, užfiksuokite reikiamus nuorodų elementus $ ženklu ir nukopijuokite ją į likusius vaisių ir daržovių langelius. Išlaikykite buvusį langelių formatą. Įrašykite likusias galutinių sumų formules. Išlaikykite buvusį langelių formatą
B31: Prekės kategorija | C31: Pavadinimas | D31: Kainos | E31: Kiekis, kg | H31: Iš viso, kg | I31: Suma, Eur | J31: Suma, Eur | M31: Komisiniai, Eur | P31: d turi dolerio zenkla or 34 ne, d fiksuojame o pavadinimas keiciasi
M32: 0.15
E33: vasaris | F33: kovas | G33: balandis | J33: vasaris | K33: kovas | L33: balandis | M33: vasaris | N33: kovas | O33: balandis
B34: Vaisiai ir uogos | C34: Obuoliai | D34: 0.9 | E34: 250 | F34: 350 | G34: 410 | H34: =SUM(E34:G34) -> 1010 | I34: =+D34*H34 -> 909 | J34: =$D34*E34 -> 225 | K34: =$D34*F34 -> 315 | L34: =$D34*G34 -> 369 | M34: =$M$32*J34 -> 33.75 | N34: =$M$32*K34 -> 47.25 | O34: =$M$32*L34 -> 55.35
C35: Kriaušės | D35: 1.2 | G35: 410 | H35: =SUM(E35:G35) -> 410 | I35: =+D35*H35 -> 492 | J35: =$D35*E35 -> 0 | K35: =$D35*F35 -> 0 | L35: =$D35*G35 -> 492 | M35: =$M$32*J35 -> 0 | N35: =$M$32*K35 -> 0 | O35: =$M$32*L35 -> 73.8
C36: Slyvos | D36: 1.5 | E36: 180 | F36: 150 | G36: 165 | H36: =SUM(E36:G36) -> 495 | I36: =+D36*H36 -> 742.5 | J36: =$D36*E36 -> 270 | K36: =$D36*F36 -> 225 | L36: =$D36*G36 -> 247.5 | M36: =$M$32*J36 -> 40.5 | N36: =$M$32*K36 -> 33.75 | O36: =$M$32*L36 -> 37.125
C37: Vynuogės | D37: 1.99 | E37: 50 | F37: 56 | G37: 52 | H37: =SUM(E37:G37) -> 158 | I37: =+D37*H37 -> 314.42 | J37: =$D37*E37 -> 99.5 | K37: =$D37*F37 -> 111.44 | L37: =$D37*G37 -> 103.48 | M37: =$M$32*J37 -> 14.925 | N37: =$M$32*K37 -> 16.716 | O37: =$M$32*L37 -> 15.522
C38: Bananai | D38: 0.99 | E38: 150 | F38: 175 | G38: 164 | H38: =SUM(E38:G38) -> 489 | I38: =+D38*H38 -> 484.11 | J38: =$D38*E38 -> 148.5 | K38: =$D38*F38 -> 173.25 | L38: =$D38*G38 -> 162.36 | M38: =$M$32*J38 -> 22.275 | N38: =$M$32*K38 -> 25.9875 | O38: =$M$32*L38 -> 24.354
C39: Citrinos | D39: 1.55 | E39: 30 | F39: 21 | G39: 27 | H39: =SUM(E39:G39) -> 78 | I39: =+D39*H39 -> 120.9 | J39: =$D39*E39 -> 46.5 | K39: =$D39*F39 -> 32.55 | L39: =$D39*G39 -> 41.85 | M39: =$M$32*J39 -> 6.975 | N39: =$M$32*K39 -> 4.8825 | O39: =$M$32*L39 -> 6.2775
C40: Apelsinai | D40: 1.8 | E40: 120 | F40: 99 | G40: 110 | H40: =SUM(E40:G40) -> 329 | I40: =+D40*H40 -> 592.2 | J40: =$D40*E40 -> 216 | K40: =$D40*F40 -> 178.2 | L40: =$D40*G40 -> 198 | M40: =$M$32*J40 -> 32.4 | N40: =$M$32*K40 -> 26.73 | O40: =$M$32*L40 -> 29.7
C41: Kiviai | D41: 2.5 | H41: =SUM(E41:G41) -> 0 | I41: =+D41*H41 -> 0 | J41: =$D41*E41 -> 0 | K41: =$D41*F41 -> 0 | L41: =$D41*G41 -> 0 | M41: =$M$32*J41 -> 0 | N41: =$M$32*K41 -> 0 | O41: =$M$32*L41 -> 0
C42: Melionai | D42: 3.5 | E42: 45 | F42: 75 | G42: 63 | H42: =SUM(E42:G42) -> 183 | I42: =+D42*H42 -> 640.5 | J42: =$D42*E42 -> 157.5 | K42: =$D42*F42 -> 262.5 | L42: =$D42*G42 -> 220.5 | M42: =$M$32*J42 -> 23.625 | N42: =$M$32*K42 -> 39.375 | O42: =$M$32*L42 -> 33.075
B43: Vaisiai ir uogos iš viso: | D43: =SUM(D34:D42) -> 15.93 | E43: =SUM(E34:E42) -> 825 | F43: =SUM(F34:F42) -> 926 | G43: =SUM(G34:G42) -> 1401 | H43: =SUM(H34:H42) -> 3152 | I43: =SUM(I34:I42) -> 4295.63 | J43: =SUM(J34:J42) -> 1163 | K43: =SUM(K34:K42) -> 1297.94 | ... O43: =SUM(O34:O42) -> 275.2035
B45: 8. | C45: =("Langelyje D"&ROW(D48)&" įrašykite formulę su nuorodų fiksavimu taip, kad ją nukopijavę į likusius 99 langelius gautume daugybos lentelę ") -> Langelyje D48 įrašykite formulę su nuorodų fiksavimu taip, kad ją nukopijavę į likusius 99 langelius gautume daugybos lentelę
D47: 1 | E47: 2 | F47: 3 | G47: 4 | H47: 5 | I47: 6 | J47: 7 | K47: 8 | L47: 9 | M47: 10
C48: 1 | D48: =$C48*D$47 -> 1 | E48: =$C48*E$47 -> 2 | F48: =$C48*F$47 -> 3 | G48: =$C48*G$47 -> 4 | H48: =$C48*H$47 -> 5 | I48: =$C48*I$47 -> 6 | J48: =$C48*J$47 -> 7 | K48: =$C48*K$47 -> 8 | ... M48: =$C48*M$47 -> 10
C49: 2 | D49: =$C49*D$47 -> 2 | E49: =$C49*E$47 -> 4 | F49: =$C49*F$47 -> 6 | G49: =$C49*G$47 -> 8 | H49: =$C49*H$47 -> 10 | I49: =$C49*I$47 -> 12 | J49: =$C49*J$47 -> 14 | K49: =$C49*K$47 -> 16 | ... M49: =$C49*M$47 -> 20
C50: 3 | D50: =$C50*D$47 -> 3 | E50: =$C50*E$47 -> 6 | F50: =$C50*F$47 -> 9 | G50: =$C50*G$47 -> 12 | H50: =$C50*H$47 -> 15 | I50: =$C50*I$47 -> 18 | J50: =$C50*J$47 -> 21 | K50: =$C50*K$47 -> 24 | ... M50: =$C50*M$47 -> 30
C51: 4 | D51: =$C51*D$47 -> 4 | E51: =$C51*E$47 -> 8 | F51: =$C51*F$47 -> 12 | G51: =$C51*G$47 -> 16 | H51: =$C51*H$47 -> 20 | I51: =$C51*I$47 -> 24 | J51: =$C51*J$47 -> 28 | K51: =$C51*K$47 -> 32 | ... M51: =$C51*M$47 -> 40
...

Sheet U6
B1: U6 | C1: Sąlyginis formatavimas (CONDITIONAL FORMATTING);
B3: Langelių paryškinimas
B4: 1. | C4: Pasirinkite tokį sąlyginį kainos formatą, kuris paryškina kainas, didesnes kaip 100 Eur
B5: 2. | C5: Papildykite formatavimo sąlygas su kainos, mažesnės kaip 150 Eur, paryškinimu
B6: 3. | C6: Formatavimo ypatumai, jei formatavimo kriterijai persidengia
B7: 4. | C7: Papildykite formatavimo sąlygas, pagal kurias būtų paryškinti šaldytuvų pardavimai
B8: 5. | C8: Papildykite formatavimo sąlygas, pagal kurias būtų paryškinti pasikartojantys duomenų įrašai (sąskaitų numeriai)
B9: 6. | C9: Tarkime, šiandien 2019-06-01. Paryškinkite datas, kurioms sąskaitos jau turėjo būti apmokėtos
B10: 7. | C10: Pakeiskite formatavimo sąlygas taip, kad būtų galima keisti formatavimo ribines reikšmes be formatavimo komandos perdarymo
E11: Kainos > | F11: 100
E12: Kainos < | F12: 150
E13: Prekė | F13: Dulkių siurblys
B15: Data | C15: Sąskaita | D15: Prekė | E15: Pardavėjas | F15: Kaina | G15: Apmokėti iki | H15: Patvirtinimas
B16: 43587 | C16: SF-030590 | D16: Skalbimo mašina SAMSUNG | E16: Petras | F16: 310 | G16: =+B16+5 -> 43592 | H16: Apmokėta
B17: 43605 | C17: SF-030608 | D17: Dulkių siurblys SAMSUNG | E17: Jonas | F17: 150 | G17: =+B17+5 -> 43610 | H17: Apmokėta
B18: 43607 | C18: SF-030611 | D18: Skalbimo mašina WHIRPOOL | E18: Jonas | F18: 275 | G18: =+B18+5 -> 43612
B19: 43591 | C19: SF-030594 | D19: Skalbimo mašina SAMSUNG | E19: Jonas | F19: 310 | G19: =+B19+5 -> 43596 | H19: Apmokėta
B20: 43613 | C20: SF-030618 | D20: Skalbimo mašina WHIRPOOL | E20: Antanas | F20: 275 | G20: =+B20+5 -> 43618
B21: 43601 | C21: SF-030605 | D21: Skalbimo mašina BEKO | E21: Jonas | F21: 260 | G21: =+B21+5 -> 43606 | H21: Apmokėta
B22: 43587 | C22: SF-030589 | D22: Šaldytuvas ZANUSSI | E22: Antanas | F22: 140 | G22: =+B22+5 -> 43592 | H22: Apmokėta
B23: 43608 | C23: SF-030614 | D23: Dulkių siurblys DAEWOO | E23: Jonas | F23: 33 | G23: =+B23+5 -> 43613
B24: 43608 | C24: SF-030612 | D24: Šaldytuvas SNAIGĖ | E24: Petras | F24: 150 | G24: =+B24+5 -> 43613 | H24: Apmokėta
B25: 43606 | C25: SF-030609 | D25: Dulkių siurblys DAEWOO | E25: Jonas | F25: 33 | G25: =+B25+5 -> 43611
B26: 43616 | C26: SF-030622 | D26: Dulkių siurblys SENCOR | E26: Antanas | F26: 55 | G26: =+B26+5 -> 43621
B27: 43599 | C27: SF-030603 | D27: Skalbimo mašina ZANUSSI | E27: Jonas | F27: 230 | G27: =+B27+5 -> 43604 | H27: Apmokėta
B28: 43612 | C28: SF-030617 | D28: Skalbimo mašina BEKO | E28: Petras | F28: 260 | G28: =+B28+5 -> 43617 | H28: Apmokėta
B29: 43594 | C29: SF-030598 | D29: Šaldytuvas SAMSUNG | E29: Jonas | F29: 460 | G29: =+B29+5 -> 43599 | H29: Apmokėta
B30: 43588 | C30: SF-030592 | D30: Dulkių siurblys PHILIPS | E30: Antanas | F30: 235 | G30: =+B30+5 -> 43593 | H30: Apmokėta
B31: 43615 | C31: SF-030621 | D31: Dulkių siurblys DAEWOO | E31: Petras | F31: 33 | G31: =+B31+5 -> 43620
B32: 43601 | C32: SF-030604 | D32: Skalbimo mašina GORENJE | E32: Petras | F32: 250 | G32: =+B32+5 -> 43606 | H32: Apmokėta
B33: 43594 | C33: SF-030596 | D33: Šaldytuvas ZANUSSI | E33: Petras | F33: 140 | G33: =+B33+5 -> 43599 | H33: Apmokėta
B34: 43615 | C34: SF-030620 | D34: Dulkių siurblys SAMSUNG | E34: Petras | F34: 150 | G34: =+B34+5 -> 43620
B35: 43614 | C35: SF-030619 | D35: Dulkių siurblys PHILIPS | E35: Petras | F35: 235 | G35: =+B35+5 -> 43619 | H35: Apmokėta
B36: 43588 | C36: SF-030593 | D36: Dulkių siurblys DAEWOO | E36: Antanas | F36: 33 | G36: =+B36+5 -> 43593 | H36: Apmokėta
B37: 43598 | C37: SF-030600 | D37: Šaldytuvas SNAIGĖ | E37: Antanas | F37: 150 | G37: =+B37+5 -> 43603 | H37: Apmokėta
B38: 43612 | C38: SF-030617 | D38: Skalbimo mašina BEKO | E38: Petras | F38: 260 | G38: =+B38+5 -> 43617
B39: 43594 | C39: SF-030597 | D39: Šaldytuvas LG | E39: Antanas | F39: 1100 | G39: =+B39+5 -> 43599 | H39: Apmokėta
B40: 43612 | C40: SF-030616 | D40: Dulkių siurblys PHILIPS | E40: Antanas | F40: 235 | G40: =+B40+5 -> 43617
B41: 43609 | C41: SF-030615 | D41: Šaldytuvas SNAIGĖ | E41: Antanas | F41: 150 | G41: =+B41+5 -> 43614
B42: 43598 | C42: SF-030601 | D42: Šaldytuvas BEKO | E42: Petras | F42: 190 | G42: =+B42+5 -> 43603 | H42: Apmokėta
...

Sheet U6A
B1: U6A | C1: Sąlyginis formatavimas (CONDITIONAL FORMATTING);
B3: 8. | C3: Sąlyginio formatavimo formulėmis sudarykite darbų vizualinį grafiką.
B5: Procesas | C5: Proceso trukmė dienomis | D5: Proceso pradžia | E5: Proceso pabaiga | F5: 2019 m. sausio mėnuo
F6: =+D7 -> 43467 | G6: =+F6+1 -> 43468 | H6: =+G6+1 -> 43469 | I6: =+H6+1 -> 43470 | J6: =+I6+1 -> 43471 | K6: =+J6+1 -> 43472 | L6: =+K6+1 -> 43473 | M6: =+L6+1 -> 43474 | N6: =+M6+1 -> 43475 | ... AH6: =+AG6+1 -> 43495
B7: Apsirūpinimas m-gomis | C7: 3 | D7: 43467 | E7: =+D7+C7 -> 43470
B8: Metalo konstrukcijų montavimas | C8: 4 | D8: =+E7+1 -> 43471 | E8: =+D8+C8 -> 43475
B9: Vamzdynų klojimas, virinimas | C9: 7 | D9: =+E8+1 -> 43476 | E9: =+D9+C9 -> 43483
B10: Technologinių aparatų montavimas | C10: 6 | D10: =+E9+1 -> 43484 | E10: =+D10+C10 -> 43490
B11: Darbų kokybės tikrinimas | C11: 2 | D11: =+E10+1 -> 43491 | E11: =+D11+C11 -> 43493
C13: Duomenys, kuriuos reikia įvesti/pakeisti gelsvuose langeliuose
C14: Duomenys šiuose langeliuose yra datos, CUSTOM formate
C16: Rakt. form. | D16: =+"AND(F$"&ROW(F6)&">=$D"&ROW(D7)&";F$"&ROW(F6)&"<=$E"&ROW(E7)&")" -> AND(F$6>=$D7;F$6<=$E7)
F34: ­

Sheet U7
A1: U7 | B1: Duomenų sekos, paieška/pakeitimas, rūšiavimas, filtravimas (sudėtingasis filtravimas), SUBTOTAL
A3: 1. | B3: Naudodami automatinio duomenų įvedimo įrankį nukopijuokite šiuos duomenis žemyn ir į dešinę. Atlikite tai su FILL (DOWN, RIGHT, ...) įrankiu (HOME->EDITING->FILL PAGRINDINIS->REDAGAVIMAS->UŽPILDYTI)
B6: Skaičius
B7: 10 | C7: 10 | D7: 10 | E7: 10
B8: 10 | C8: 10 | D8: 10 | E8: 10
B9: 10 | C9: Tekstas | D9: Tekstas | E9: Tekstas
B10: 10 | C10: Prekė | D10: Tekstas | E10: Tekstas
B11: 10 | C11: Prekė | D11: Tekstas | E11: Tekstas
B12: 10 | C12: Prekė | D12: Tekstas | E12: Tekstas
B13: 10 | C13: Prekė | D13: Prekė 11 | E13: Tekstas
B14: 10 | C14: Prekė | D14: Prekė 12 | E14: Tekstas
B15: 10 | C15: Prekė | D15: Prekė 13 | E15: Data
B16: 10 | C16: Prekė | D16: Prekė 14 | E16: 43658
B17: 10 | C17: Prekė | D17: Prekė 15 | E17: 43659
A19: 2. | B19: Kopijavimo žemyn būdu nukopijuokite šias sekas žemyn per 5 eilutes
B21: 10 | C21: 43466 | D21: 43466 | E21: 43466
B22: 8 | C22: 43475 | D22: 43497 | E22: 43831
A29: 3. | B29: Naudodamiesi SERIES SEKA įrankiu sudarykite datų seką žemyn, kurioje būtų kas antra mėnesio darbo diena
B30: 43647 | C30: 43831
B31: 43649 | C31: 43922
B32: 43651 | C32: 44013
B33: 43653 | C33: 44105
B34: 43655 | C34: 44197
B35: 43657 | C35: 44287
B36: 43659 | C36: 44378
B37: 43661 | C37: 44470
B38: 43663 | C38: 44562
B39: 43665 | C39: 44652
B40: 43667
B41: 43669
B42: 43671
A43: 4. | B43: Nukopijuokite duomenis dešinėn | F43: FILE-OPTIONS-ADVANCED-EDIT CUSTOM LIST
B44: January | C44: February | D44: March | E44: April | F44: How to copy a list and add it to make it outomatic
B45: Jan | C45: Feb | D45: Mar | E45: Apr
B46: Monday | C46: Tuesday | D46: Wednesday | E46: Thursday
B47: Mon | C47: Tue | D47: Wed | E47: Thu
B48: Pr | C48: Pr | D48: Pr | E48: Pr
B49: Pirmadienis | C49: Pirmadienis | D49: Pirmadienis | E49: Pirmadienis
B50: Saus | C50: Saus | D50: Saus | E50: Saus
A52: 5. | B52: Užpildykite kelis prekių užsakymus pasinaudodami automatiškai sudaromais sąrašais (PICK UP FROM DROP-DOWN LIST IŠSIRINKTI IŠ IŠPLEČIAMOJO SĄRAŠO)
...

Sheet U7A
B1: U7A | C1: Duomenų sekos, paieška/pakeitimas, rūšiavimas, filtravimas (sudėtingasis filtravimas), SUBTOTAL
B3: 9. | C3: Lentelėje apačioje sudarykite filtrą, kuriuo naudodamiesi pamatytumėte visas 2018 m. sausio mėnesį "Rokiškio pieno" patiektas prekes.
B4: 10. | C4: Naudodami datos filtrus pakeiskite filtravimo kriterijų į bet kurių metų sausio mėnesius DATE FILTERS->ALL DATES IN THE PERIOD->JANUARY DATŲ FILTRAI->VISOS LAIKOTARPIO DATOS->SAUSIS.
B5: 11. | C5: Naudodami CUSTOM FILTER PASIRINKTINĮ FILTRĄ nustatytus filtravimo kriterijus papildykite dar vienu: rodyti tik tuos duomenis, kuriuose kiekis yra >=20 ir <=30.
B6: 12. | C6: Naudodami funkciją SUBTOTAL gaukite matomų ekrane filtruotų duomenų skaičiavimus (SUM, MIN, MAX, AVERAGE, COUNT) kiekiams ir pinigų sumoms:
F7: Suma, Eur | H7: Suma, Eur
E8: SUM | F8: =SUM(H289:H312) -> 551.87 | H8: =SUBTOTAL(9,H289:H312) -> 551.87 | J8: Suma | M8: Galima filtruoti pagal spalva arba srifto spalva
E9: AVERAGE | F9: =AVERAGE(H289:H312) -> 22.994583 | H9: =SUBTOTAL(1,H289:H312) -> 22.994583 | J9: Vidurkis
E10: MIN | F10: =MIN(H289:H312) -> 9.81 | H10: =SUBTOTAL(5,H289:H312) -> 9.81 | J10: Minimumas
E11: MAX | F11: =MAX(H289:H312) -> 53 | H11: =SUBTOTAL(4,H289:H312) -> 53 | J11: Maksimumas
E12: COUNT | F12: =COUNT(H289:H312) -> 24 | H12: =SUBTOTAL(2,H289:H312) -> 24 | J12: Kiekis (langelių, užpildytų skaičiais)
B13: 13. | C13: Išskleiskite (pliuso ženklas kairėje)
C15: Išplėstinio filtro pagalba išsręskite šias užduotis: | G15: Data - advanced | I15: Padaryti atra filtra su velavimais, keisis tik vidurinysis, nukopijuoti langaeli
C16: a) Iš lentelės apačioje duomenų sudarykite unikalų prekių sąrašą
C17: b) Iš lentelės apačioje duomenų suformuokite vėlavių atsiskaitymų santrauką
C20: Data | D20: Prekės pavadinimas | E20: Tiekėjas | F20: Kiekis, vnt. | G20: Kaina, Eur | H20: Suma, Eur | I20: Mokėti iki | J20: Atsisk. data | K20: Ar sumokėta | L20: Vėlavimai
D21: Dvaro varškė | F21: >=15 | L21: =+IF(ISBLANK(J29),FALSE(),J29>I29) -> FALSE
N27: Data | O27: Prekės pavadinimas | P27: Tiekėjas | Q27: Kiekis, vnt. | R27: Kaina, Eur | S27: Suma, Eur | T27: Mokėti iki | U27: Atsisk. data | V27: Ar sumokėta
C28: Data | D28: Prekės pavadinimas | E28: Tiekėjas | F28: Kiekis, vnt. | G28: Kaina, Eur | H28: Suma, Eur | I28: Mokėti iki | J28: Atsisk. data | K28: Ar sumokėta | N28: 42737 | O28: Dvaro varškė | P28: Pieno žvaigždės | Q28: 20 | R28: 2.12 | S28: 42.4 | T28: 42762 | U28: 42761 | V28: Sumokėta
C29: 42736 | D29: Rokiškio naminis pienas | E29: Rokiškio pienas | F29: 20 | G29: 1.55 | H29: =F29*G29 -> 31 | I29: =+C29+25 -> 42761 | J29: 42758 | K29: Sumokėta | N29: 42742 | O29: Dvaro varškė | P29: Pieno žvaigždės | Q29: 15 | R29: 2.12 | S29: 31.8 | T29: 42767 | U29: 42765 | V29: Sumokėta
C30: 42737 | D30: Dvaro varškė | E30: Pieno žvaigždės | F30: 20 | G30: 2.12 | H30: =F30*G30 -> 42.4 | I30: =+C30+25 -> 42762 | J30: 42761 | K30: Sumokėta | N30: 42743 | O30: Dvaro varškė | P30: Pieno žvaigždės | Q30: 21 | R30: 2.12 | S30: 44.52 | T30: 42768 | U30: 42768 | V30: Sumokėta
C31: 42738 | D31: Smetoniškas sviestas | E31: Pieno žvaigždės | F31: 9 | G31: 2.02 | H31: =F31*G31 -> 18.18 | I31: =+C31+25 -> 42763 | J31: 42762 | K31: Sumokėta | N31: 42767 | O31: Dvaro varškė | P31: Pieno žvaigždės | Q31: 22 | R31: 2.12 | S31: 46.64 | T31: 42792 | U31: 42792 | V31: Sumokėta
C32: 42739 | D32: Rokiškio naminis pienas | E32: Rokiškio pienas | F32: 24 | G32: 1.55 | H32: =F32*G32 -> 37.2 | I32: =+C32+25 -> 42764 | J32: 42763 | K32: Sumokėta | N32: 42771 | O32: Dvaro varškė | P32: Pieno žvaigždės | Q32: 20 | R32: 2.12 | S32: 42.4 | T32: 42796 | U32: 42794 | V32: Sumokėta
C33: 42742 | D33: Dvaro varškė | E33: Pieno žvaigždės | F33: 15 | G33: 2.12 | H33: =F33*G33 -> 31.8 | I33: =+C33+25 -> 42767 | J33: 42765 | K33: Sumokėta | N33: 42788 | O33: Dvaro varškė | P33: Pieno žvaigždės | Q33: 17 | R33: 2.12 | S33: 36.04 | T33: 42813 | U33: 42813 | V33: Sumokėta
C34: 42743 | D34: Dvaro varškė | E34: Pieno žvaigždės | F34: 21 | G34: 2.12 | H34: =F34*G34 -> 44.52 | I34: =+C34+25 -> 42768 | J34: 42768 | K34: Sumokėta | N34: 42791 | O34: Dvaro varškė | P34: Pieno žvaigždės | Q34: 22 | R34: 2.12 | S34: 46.64 | T34: 42816 | U34: 42815 | V34: Sumokėta
C35: 42744 | D35: Dvaro varškė | E35: Pieno žvaigždės | F35: 8 | G35: 2.12 | H35: =F35*G35 -> 16.96 | I35: =+C35+25 -> 42769 | J35: 42770 | K35: Sumokėta | N35: 42795 | O35: Dvaro varškė | P35: Pieno žvaigždės | Q35: 16 | R35: 2.12 | S35: 33.92 | T35: 42820 | U35: 42819 | V35: Sumokėta
C36: 42745 | D36: Dvaro varškė | E36: Pieno žvaigždės | F36: 10 | G36: 2.12 | H36: =F36*G36 -> 21.2 | I36: =+C36+25 -> 42770 | J36: 42770 | K36: Sumokėta | N36: 42798 | O36: Dvaro varškė | P36: Pieno žvaigždės | Q36: 15 | R36: 2.12 | S36: 31.8 | T36: 42823 | U36: 42822 | V36: Sumokėta
C37: 42746 | D37: Rūkytas lydytas sūris "Visiems" | E37: Rokiškio pienas | F37: 15 | G37: 1.4 | H37: =F37*G37 -> 21 | I37: =+C37+25 -> 42771 | J37: 42770 | K37: Sumokėta | N37: 42821 | O37: Dvaro varškė | P37: Pieno žvaigždės | Q37: 25 | R37: 2.12 | S37: 53 | T37: 42846 | U37: 42846 | V37: Sumokėta
C38: 42749 | D38: Grietinė "Žaloji karvutė" | E38: Rokiškio pienas | F38: 9 | G38: 1.09 | H38: =F38*G38 -> 9.81 | I38: =+C38+25 -> 42774 | J38: 42772 | K38: Sumokėta | N38: 42836 | O38: Dvaro varškė | P38: Pieno žvaigždės | Q38: 23 | R38: 2.12 | S38: 48.76 | T38: 42861 | U38: 42861 | V38: Sumokėta
C39: 42750 | D39: Rokiškio naminis pienas | E39: Rokiškio pienas | F39: 23 | G39: 1.55 | H39: =F39*G39 -> 35.65 | I39: =+C39+25 -> 42775 | J39: 42773 | K39: Sumokėta | N39: 42842 | O39: Dvaro varškė | P39: Pieno žvaigždės | Q39: 17 | R39: 2.12 | S39: 36.04 | T39: 42867 | U39: 42865 | V39: Sumokėta
C40: 42751 | D40: Smetoniškas sviestas | E40: Pieno žvaigždės | F40: 15 | G40: 2.02 | H40: =F40*G40 -> 30.3 | I40: =+C40+25 -> 42776 | J40: 42776 | K40: Sumokėta | N40: 42862 | O40: Dvaro varškė | P40: Pieno žvaigždės | Q40: 21 | R40: 2.12 | S40: 44.52 | T40: 42887 | U40: 42887 | V40: Sumokėta
... C106: 42843 | D106: Dvaro varškė | E106: Pieno žvaigždės | F106: 10 | G106: 2.12 | H106: =F106*G106 -> 21.2 | I106: =+C106+25 -> 42868 | J106: 42868 | K106: Sumokėta | N106: 43592 | O106: Dvaro varškė | P106: Pieno žvaigždės | Q106: 23 | R106: 2.35 | S106: 54.05 | T106: 43617 | U106: 43616 | V106: Sumokėta
C107: 42844 | D107: Rokiškio naminis pienas | E107: Rokiškio pienas | F107: 21 | G107: 1.55 | H107: =F107*G107 -> 32.55 | I107: =+C107+25 -> 42869 | J107: 42870 | K107: Sumokėta | N107: 43645 | O107: Dvaro varškė | P107: Pieno žvaigždės | Q107: 19 | R107: 2.35 | S107: 44.65 | T107: 43670 | V107: Nesumokėta
C108: 42847 | D108: Smetoniškas sviestas | E108: Pieno žvaigždės | F108: 17 | G108: 2.02 | H108: =F108*G108 -> 34.34 | I108: =+C108+25 -> 42872 | J108: 42871 | K108: Sumokėta | N108: 43648 | O108: Dvaro varškė | P108: Pieno žvaigždės | Q108: 18 | R108: 2.35 | S108: 42.3 | T108: 43673 | V108: Nesumokėta
C109: 42848 | D109: Smetoniškas sviestas | E109: Pieno žvaigždės | F109: 18 | G109: 2.02 | H109: =F109*G109 -> 36.36 | I109: =+C109+25 -> 42873 | J109: 42872 | K109: Sumokėta | N109: 43661 | O109: Dvaro varškė | P109: Pieno žvaigždės | Q109: 16 | R109: 2.35 | S109: 37.6 | T109: 43686 | V109: Nesumokėta
C110: 42849 | D110: Grietinė "Žaloji karvutė" | E110: Rokiškio pienas | F110: 15 | G110: 1.09 | H110: =F110*G110 -> 16.35 | I110: =+C110+25 -> 42874 | J110: 42872 | K110: Sumokėta | N110: 43666 | O110: Dvaro varškė | P110: Pieno žvaigždės | Q110: 21 | R110: 2.35 | S110: 49.35 | T110: 43691 | V110: Nesumokėta
C111: 42850 | D111: Smetoniškas sviestas | E111: Pieno žvaigždės | F111: 12 | G111: 2.02 | H111: =F111*G111 -> 24.24 | I111: =+C111+25 -> 42875 | J111: 42875 | K111: Sumokėta
C112: 42851 | D112: Dvaro varškė | E112: Pieno žvaigždės | F112: 13 | G112: 2.12 | H112: =F112*G112 -> 27.56 | I112: =+C112+25 -> 42876 | J112: 42874 | K112: Sumokėta
C113: 42854 | D113: Rokiškio naminis pienas | E113: Rokiškio pienas | F113: 24 | G113: 1.55 | H113: =F113*G113 -> 37.2 | I113: =+C113+25 -> 42879 | J113: 42879 | K113: Sumokėta
C114: 42855 | D114: Smetoniškas sviestas | E114: Pieno žvaigždės | F114: 25 | G114: 2.02 | H114: =F114*G114 -> 50.5 | I114: =+C114+25 -> 42880 | J114: 42879 | K114: Sumokėta
...

Sheet U8
A1: U8 | B1: Duomenų jungimas, skaidymas, grupavimas;
A3: 1. | B3: Sparčiojo užpildymo būdu atkurkite trūkstamus el. pašto adresus bei sudarykite telefonų sąrašo stulpelį pagal pateiktus pavyzdžius
A5: ID | B5: VARDAS | C5: PAVARDĖ | D5: PAREIGOS | E5: TELEFONO NR. | F5: ELEKTRONINIS PAŠTAS | G5: SUJUNGTA INFORMACIJA | I5: LOWER | K5: & | L5: UPPER | M5: PROPER | N5: LEFT | O5: MID | P5: RIGHT | Q5: &
A6: 716 | B6: Egidijus | C6: Purlys | D6: Viceministras | E6: 852034409 | F6: egidijus.purlys@enmin.lt | G6: E. PURLYS, tel. 852034409 | I6: =LOWER(B5) -> vardas | J6: =LOWER(C5) -> pavardė | K6: =I6&" "&J6 -> vardas pavardė | L6: =UPPER(K6) -> VARDAS PAVARDĖ | M6: =PROPER(L6) -> Vardas Pavardė | N6: =LEFT(E6,1) -> 8 | O6: =LEFT(E6,4) -> 8520 | P6: =RIGHT(E6,5) -> 34409 | Q6: =N6&-O6&"-"&P6 -> 8-8520-34409
A7: 712 | B7: Žygimantas | C7: Vaičiūnas | D7: Ministras | E7: 852034407 | F7: žygimantas.vaičiūnas@enmin.lt | G7: Ž. VAIČIŪNAS, tel. 852034407 | I7: =LOWER(B6) -> egidijus | J7: =LOWER(C6) -> purlys | K7: =I7&" "&J7 -> egidijus purlys | L7: =UPPER(K7) -> EGIDIJUS PURLYS | M7: =PROPER(L7) -> Egidijus Purlys | N7: =LEFT(E7,1) -> 8 | O7: =LEFT(E7,4) -> 8520 | P7: =RIGHT(E7,5) -> 34407 | Q7: =N7&-O7&"-"&P7 -> 8-8520-34407
A8: 715 | B8: Lina | C8: Sabaitienė | D8: Viceministrė | E8: 852034408 | F8: lina.sabaitienė@enmin.lt | G8: L. SABAITIENĖ, tel. 852034408 | I8: =LOWER(B7) -> žygimantas | J8: =LOWER(C7) -> vaičiūnas | K8: =I8&" "&J8 -> žygimantas vaičiūnas | L8: =UPPER(K8) -> ŽYGIMANTAS VAIČIŪNAS | M8: =PROPER(L8) -> Žygimantas Vaičiūnas | N8: =LEFT(E8,1) -> 8 | O8: =LEFT(E8,4) -> 8520 | P8: =RIGHT(E8,5) -> 34408 | Q8: =N8&-O8&"-"&P8 -> 8-8520-34408
A9: 719 | B9: Aurelija | C9: Vernickaitė | D9: Ministro patarėja | E9: 852034427 | F9: aurelija.vernickaitė@enmin.lt | G9: A. VERNICKAITĖ, tel. 852034427 | I9: =LOWER(B8) -> lina | J9: =LOWER(C8) -> sabaitienė | K9: =I9&" "&J9 -> lina sabaitienė | L9: =UPPER(K9) -> LINA SABAITIENĖ | M9: =PROPER(L9) -> Lina Sabaitienė | N9: =LEFT(E9,1) -> 8 | O9: =LEFT(E9,4) -> 8520 | P9: =RIGHT(E9,5) -> 34427 | Q9: =N9&-O9&"-"&P9 -> 8-8520-34427
A10: 720 | B10: Sandra | C10: Paulavičienė | D10: Ministro padėjėja | E10: 852034407 | F10: sandra.paulavičienė@enmin.lt | G10: S. PAULAVIČIENĖ, tel. 852034407 | I10: =LOWER(B9) -> aurelija | J10: =LOWER(C9) -> vernickaitė | K10: =I10&" "&J10 -> aurelija vernickaitė | L10: =UPPER(K10) -> AURELIJA VERNICKAITĖ | M10: =PROPER(L10) -> Aurelija Vernickaitė | N10: =LEFT(E10,1) -> 8 | O10: =LEFT(E10,4) -> 8520 | P10: =RIGHT(E10,5) -> 34407 | Q10: =N10&-O10&"-"&P10 -> 8-8520-34407
A11: 724 | B11: Ramūnas | C11: Dilba | D11: Ministerijos kancleris | E11: 852034425 | F11: ramūnas.dilba@enmin.lt | G11: R. DILBA, tel. 852034425 | I11: =LOWER(B10) -> sandra | J11: =LOWER(C10) -> paulavičienė | K11: =I11&" "&J11 -> sandra paulavičienė | L11: =UPPER(K11) -> SANDRA PAULAVIČIENĖ | M11: =PROPER(L11) -> Sandra Paulavičienė | N11: =LEFT(E11,1) -> 8 | O11: =LEFT(E11,4) -> 8520 | P11: =RIGHT(E11,5) -> 34425 | Q11: =N11&-O11&"-"&P11 -> 8-8520-34425
A12: 725 | B12: Aušra | C12: Siniuvienė | D12: Kalbos tvarkytoja | E12: 852034470 | F12: aušra.siniuvienė@enmin.lt | G12: A. SINIUVIENĖ, tel. 852034470 | I12: =LOWER(B11) -> ramūnas | J12: =LOWER(C11) -> dilba | K12: =I12&" "&J12 -> ramūnas dilba | L12: =UPPER(K12) -> RAMŪNAS DILBA | M12: =PROPER(L12) -> Ramūnas Dilba | N12: =LEFT(E12,1) -> 8 | O12: =LEFT(E12,4) -> 8520 | P12: =RIGHT(E12,5) -> 34470 | Q12: =N12&-O12&"-"&P12 -> 8-8520-34470
A13: 726 | B13: Ramunė | C13: Mikalauskienė | D13: Skyriaus vedėja | E13: 852034470 | F13: ramunė.mikalauskienė@enmin.lt | G13: R. MIKALAUSKIENĖ, tel. 852034470 | I13: =LOWER(B12) -> aušra | J13: =LOWER(C12) -> siniuvienė | K13: =I13&" "&J13 -> aušra siniuvienė | L13: =UPPER(K13) -> AUŠRA SINIUVIENĖ | M13: =PROPER(L13) -> Aušra Siniuvienė | N13: =LEFT(E13,1) -> 8 | O13: =LEFT(E13,4) -> 8520 | P13: =RIGHT(E13,5) -> 34470 | Q13: =N13&-O13&"-"&P13 -> 8-8520-34470
A14: 727 | B14: Dovilė | C14: Zajauskaitė | D14: Patarėja | E14: 852034470 | F14: dovilė.zajauskaitė@enmin.lt | G14: D. ZAJAUSKAITĖ, tel. 852034470 | I14: =LOWER(B13) -> ramunė | J14: =LOWER(C13) -> mikalauskienė | K14: =I14&" "&J14 -> ramunė mikalauskienė | L14: =UPPER(K14) -> RAMUNĖ MIKALAUSKIENĖ | M14: =PROPER(L14) -> Ramunė Mikalauskienė | N14: =LEFT(E14,1) -> 8 | O14: =LEFT(E14,4) -> 8520 | P14: =RIGHT(E14,5) -> 34470 | Q14: =N14&-O14&"-"&P14 -> 8-8520-34470
A15: 728 | B15: Daiva | C15: Brazdžiuvienė | D15: Vyriausioji specialistė | E15: 852034470 | F15: daiva.brazdžiuvienė@enmin.lt | G15: D. BRAZDŽIUVIENĖ, tel. 852034470 | I15: =LOWER(B14) -> dovilė | J15: =LOWER(C14) -> zajauskaitė | K15: =I15&" "&J15 -> dovilė zajauskaitė | L15: =UPPER(K15) -> DOVILĖ ZAJAUSKAITĖ | M15: =PROPER(L15) -> Dovilė Zajauskaitė | N15: =LEFT(E15,1) -> 8 | O15: =LEFT(E15,4) -> 8520 | P15: =RIGHT(E15,5) -> 34470 | Q15: =N15&-O15&"-"&P15 -> 8-8520-34470
A16: 729 | B16: Ramunė | C16: Žičkutė-Artamonova | D16: Vyriausioji specialistė | E16: 852034470 | F16: ramunė.žičkutė-artamonova@enmin.lt | G16: R. ŽIČKUTĖ-ARTAMONOVA, tel. 852034470 | I16: =LOWER(B15) -> daiva | J16: =LOWER(C15) -> brazdžiuvienė | K16: =I16&" "&J16 -> daiva brazdžiuvienė | L16: =UPPER(K16) -> DAIVA BRAZDŽIUVIENĖ | M16: =PROPER(L16) -> Daiva Brazdžiuvienė | N16: =LEFT(E16,1) -> 8 | O16: =LEFT(E16,4) -> 8520 | P16: =RIGHT(E16,5) -> 34470 | Q16: =N16&-O16&"-"&P16 -> 8-8520-34470
A17: 730 | B17: Brigita | C17: Paulikienė | D17: Vyriausioji specialistė | E17: 852034470 | F17: brigita.paulikienė@enmin.lt | G17: B. PAULIKIENĖ, tel. 852034470 | I17: =LOWER(B16) -> ramunė | J17: =LOWER(C16) -> žičkutė-artamonova | K17: =I17&" "&J17 -> ramunė žičkutė-artamonova | L17: =UPPER(K17) -> RAMUNĖ ŽIČKUTĖ-ARTAMONOVA | M17: =PROPER(L17) -> Ramunė Žičkutė-Artamonova | N17: =LEFT(E17,1) -> 8 | O17: =LEFT(E17,4) -> 8520 | P17: =RIGHT(E17,5) -> 34470 | Q17: =N17&-O17&"-"&P17 -> 8-8520-34470
... A73: 877 | B73: Žydrė | C73: Vasiliauskienė | D73: Vyriausiasis specialistas | E73: 852034679 | F73: žydrė.vasiliauskienė@enmin.lt | G73: Ž. VASILIAUSKIENĖ, tel. 852034679 | I73: =LOWER(B72) -> gediminas | J73: =LOWER(C72) -> karalius | K73: =I73&" "&J73 -> gediminas karalius | L73: =UPPER(K73) -> GEDIMINAS KARALIUS | M73: =PROPER(L73) -> Gediminas Karalius | N73: =LEFT(E73,1) -> 8 | O73: =LEFT(E73,4) -> 8520 | P73: =RIGHT(E73,5) -> 34679 | Q73: =N73&-O73&"-"&P73 -> 8-8520-34679
A75: Jei FLASH FILL šioje EXCEL versijoje napalaikoma, naudokite formules
A76: 875 | B76: Gediminas | C76: Karalius | D76: Ministerijos patarėjas | E76: 852034472 | F76: =LOWER(B76)&"."&LOWER(C76)&"@enmin.lt" -> gediminas.karalius@enmin.lt | G76: =LEFT(B76,1)&". "&UPPER(C76)&", tel. "&E76 -> G. KARALIUS, tel. 852034472
A78: 2. | B78: Naudodamiesi sparčiojo užpildymo FALSH FILL SPARTUSIS UŽPILDYMAS įrankiu užpildykite tuščius langelius
C80: Vardas PAVARDĖ
C81: Jonas PETRAITIS | D81: Petraitis
C82: Violeta GREIČIUVIENĖ | D82: Greičiuvienė
C83: Vytautas BERNADIŠIUS | D83: Bernadišius
C84: Žydrė VASILIAUSKIENĖ | D84: Vasiliauskienė
C85: Žygimantas VAIČIŪNAS | D85: Vaičiūnas
A87: Jei FLASH FILL šioje EXCEL versijoje napalaikoma, naudokite formules
C88: Jonas PETRAITIS | D88: =PROPER(REPLACE(C88,1,FIND(" ",C88),"")) -> Petraitis
A90: 3. | B90: Naudodamiesi įrankiu TEXT TO COLLUMNS TEKSTĄ Į STULPELIUS perkelkite į EXCEL formatą CSV duomenis
A92: Date | B92: Ordered Product Sales | C92: Ordered Product Sales – B2B | D92: Units Ordered | E92: Units Ordered – B2B | F92: Total Order Items | G92: Total Order Items – B2B
A93: 43617 | B93: 96.97 | C93: 0 | D93: 4 | E93: 0 | F93: 4 | G93: 0
A94: 43618 | B94: 174.95 | C94: 0 | D94: 8 | E94: 0 | F94: 8 | G94: 0
A95: 43619 | B95: 64.99 | C95: 0 | D95: 4 | E95: 0 | F95: 4 | G95: 0
A96: 43620 | B96: 34.97 | C96: 0 | D96: 2 | E96: 0 | F96: 2 | G96: 0
A97: 43621 | B97: 89.96 | C97: 0 | D97: 6 | E97: 0 | F97: 6 | G97: 0
A98: 43622 | B98: 74.97 | C98: 0 | D98: 5 | E98: 0 | F98: 5 | G98: 0
A99: 43623 | B99: 44.99 | C99: 0 | D99: 3 | E99: 0 | F99: 3 | G99: 0
A100: 43624 | B100: 44.99 | C100: 0 | D100: 3 | E100: 0 | F100: 3 | G100: 0
A101: 43625 | B101: 55.97 | C101: 0 | D101: 3 | E101: 0 | F101: 3 | G101: 0
A102: 43626 | B102: 36.9 | C102: 0 | D102: 2 | E102: 0 | F102: 2 | G102: 0
A103: 43627 | B103: 89.96 | C103: 0 | D103: 6 | E103: 0 | F103: 6 | G103: 0
...

Sheet U8A
A1: U8A | B1: Duomenų jungimas, skaidymas, grupavimas;
B2: 4.
C3: Saus | D3: Vas | E3: Kov | F3: 2018 I ketv | G3: Bal | H3: Geg | I3: Birž | J3: 2018 II ketv | K3: Liep | L3: Rugp | M3: Rugs | N3: 2018 III ketv | O3: Spal | P3: Lapkr | Q3: Gruod | R3: 2018 IV ketv | S3: 2018 metai | T3: Saus | U3: Vas | V3: Kov | W3: 2019 I ketv | X3: Bal | Y3: Geg | Z3: Birž | AA3: 2019 II ketv | AB3: Liep | AC3: Rugp | AD3: Rugs | AE3: 2019 III ketv | AF3: Spal | AG3: Lapkr | AH3: Gruod | AI3: 2019 IV ketv | AJ3: 2019 metai
B4: Elektros įrangos pajamos | C4: 2046 | D4: 2057 | E4: 2067 | F4: =+SUM(C4:E4) -> 6170 | G4: 2028 | H4: 2044 | I4: 2085 | J4: =+SUM(G4:I4) -> 6157 | K4: 2023 | L4: 2016 | M4: 2048 | N4: =+SUM(K4:M4) -> 6087 | O4: 2079 | P4: 2091 | Q4: 2030 | R4: =+SUM(O4:Q4) -> 6200 | S4: =+F4+J4+N4+R4 -> 24614 | T4: 2053 | U4: 2084 | V4: 2085 | W4: =+SUM(T4:V4) -> 6222 | X4: 2026 | Y4: 2043 | Z4: 2024 | AA4: =+SUM(X4:Z4) -> 6093 | AE4: =+SUM(AB4:AD4) -> 0 | AI4: =+SUM(AF4:AH4) -> 0 | AJ4: =+W4+AA4+AE4+AI4 -> 12315
B5: Dujinės įrangos pajamos | C5: 2592 | D5: 2517 | E5: 2550 | F5: =+SUM(C5:E5) -> 7659 | G5: 2570 | H5: 2505 | I5: 2576 | J5: =+SUM(G5:I5) -> 7651 | K5: 2522 | L5: 2517 | M5: 2577 | N5: =+SUM(K5:M5) -> 7616 | O5: 2511 | P5: 2557 | Q5: 2516 | R5: =+SUM(O5:Q5) -> 7584 | S5: =+F5+J5+N5+R5 -> 30510 | T5: 2523 | U5: 2504 | V5: 2588 | W5: =+SUM(T5:V5) -> 7615 | X5: 2571 | Y5: 2504 | Z5: 2507 | AA5: =+SUM(X5:Z5) -> 7582 | AE5: =+SUM(AB5:AD5) -> 0 | AI5: =+SUM(AF5:AH5) -> 0 | AJ5: =+W5+AA5+AE5+AI5 -> 15197
B6: Skysto kuro įrangos pajamos | C6: 4091 | D6: 4033 | E6: 4054 | F6: =+SUM(C6:E6) -> 12178 | G6: 4082 | H6: 4065 | I6: 4057 | J6: =+SUM(G6:I6) -> 12204 | K6: 4037 | L6: 4095 | M6: 4039 | N6: =+SUM(K6:M6) -> 12171 | O6: 4038 | P6: 4031 | Q6: 4035 | R6: =+SUM(O6:Q6) -> 12104 | S6: =+F6+J6+N6+R6 -> 48657 | T6: 4034 | U6: 4073 | V6: 4016 | W6: =+SUM(T6:V6) -> 12123 | X6: 4021 | Y6: 4014 | Z6: 4085 | AA6: =+SUM(X6:Z6) -> 12120 | AE6: =+SUM(AB6:AD6) -> 0 | AI6: =+SUM(AF6:AH6) -> 0 | AJ6: =+W6+AA6+AE6+AI6 -> 24243
B7: Kieto kuro įrangos pajamos | C7: 1501 | D7: 1510 | E7: 1551 | F7: =+SUM(C7:E7) -> 4562 | G7: 1536 | H7: 1502 | I7: 1557 | J7: =+SUM(G7:I7) -> 4595 | K7: 1522 | L7: 1516 | M7: 1529 | N7: =+SUM(K7:M7) -> 4567 | O7: 1500 | P7: 1509 | Q7: 1554 | R7: =+SUM(O7:Q7) -> 4563 | S7: =+F7+J7+N7+R7 -> 18287 | T7: 1519 | U7: 1540 | V7: 1518 | W7: =+SUM(T7:V7) -> 4577 | X7: 1559 | Y7: 1533 | Z7: 1521 | AA7: =+SUM(X7:Z7) -> 4613 | AE7: =+SUM(AB7:AD7) -> 0 | AI7: =+SUM(AF7:AH7) -> 0 | AJ7: =+W7+AA7+AE7+AI7 -> 9190
B8: Įrangos pardavimas iš viso | C8: =+SUBTOTAL(9,C4:C7) -> 10230 | D8: =+SUBTOTAL(9,D4:D7) -> 10117 | E8: =+SUBTOTAL(9,E4:E7) -> 10222 | F8: =+SUBTOTAL(9,F4:F7) -> 30569 | G8: =+SUBTOTAL(9,G4:G7) -> 10216 | H8: =+SUBTOTAL(9,H4:H7) -> 10116 | I8: =+SUBTOTAL(9,I4:I7) -> 10275 | J8: =+SUBTOTAL(9,J4:J7) -> 30607 | ... AJ8: =+SUBTOTAL(9,AJ4:AJ7) -> 60945
B9: Įrangos montavimas ir priežiūra | C9: =+ROUND(C8*0.3,0) -> 3069 | D9: =+ROUND(D8*0.3,0) -> 3035 | E9: =+ROUND(E8*0.3,0) -> 3067 | F9: =+ROUND(F8*0.3,0) -> 9171 | G9: =+ROUND(G8*0.3,0) -> 3065 | H9: =+ROUND(H8*0.3,0) -> 3035 | I9: =+ROUND(I8*0.3,0) -> 3083 | J9: =+ROUND(J8*0.3,0) -> 9182 | ... AJ9: =+ROUND(AJ8*0.3,0) -> 18284
B10: VISOS PAJAMOS | C10: =+SUBTOTAL(9,C4:C9) -> 13299 | D10: =+SUBTOTAL(9,D4:D9) -> 13152 | E10: =+SUBTOTAL(9,E4:E9) -> 13289 | F10: =+SUBTOTAL(9,F4:F9) -> 39740 | G10: =+SUBTOTAL(9,G4:G9) -> 13281 | H10: =+SUBTOTAL(9,H4:H9) -> 13151 | I10: =+SUBTOTAL(9,I4:I9) -> 13358 | J10: =+SUBTOTAL(9,J4:J9) -> 39789 | ... AJ10: =+SUBTOTAL(9,AJ4:AJ9) -> 79229
B11: Metalo profiliai ir skarda | C11: 3325 | D11: 3288 | E11: 3322 | F11: =+SUM(C11:E11) -> 9935 | G11: 3320 | H11: 3288 | I11: 3340 | J11: =+SUM(G11:I11) -> 9948 | K11: 3284 | L11: 3297 | M11: 3313 | N11: =+SUM(K11:M11) -> 9894 | O11: 3292 | P11: 3311 | Q11: 3294 | R11: =+SUM(O11:Q11) -> 9897 | S11: =+F11+J11+N11+R11 -> 39674 | T11: 3292 | U11: 3315 | V11: 3317 | W11: =+SUM(T11:V11) -> 9924 | X11: 3308 | Y11: 3281 | Z11: 3295 | AA11: =+SUM(X11:Z11) -> 9884 | AE11: =+SUM(AB11:AD11) -> 0 | AI11: =+SUM(AF11:AH11) -> 0 | AJ11: =+W11+AA11+AE11+AI11 -> 19808
B12: Komplektavimo detalės | C12: 665 | D12: 658 | E12: 664 | F12: =+SUM(C12:E12) -> 1987 | G12: 664 | H12: 658 | I12: 668 | J12: =+SUM(G12:I12) -> 1990 | K12: 657 | L12: 659 | M12: 663 | N12: =+SUM(K12:M12) -> 1979 | O12: 658 | P12: 662 | Q12: 659 | R12: =+SUM(O12:Q12) -> 1979 | S12: =+F12+J12+N12+R12 -> 7935 | T12: 658 | U12: 663 | V12: 663 | W12: =+SUM(T12:V12) -> 1984 | X12: 662 | Y12: 656 | Z12: 659 | AA12: =+SUM(X12:Z12) -> 1977 | AE12: =+SUM(AB12:AD12) -> 0 | AI12: =+SUM(AF12:AH12) -> 0 | AJ12: =+W12+AA12+AE12+AI12 -> 3961
B13: Pagalbinės medžiagos | C13: 333 | D13: 329 | E13: 332 | F13: =+SUM(C13:E13) -> 994 | G13: 332 | H13: 329 | I13: 334 | J13: =+SUM(G13:I13) -> 995 | K13: 329 | L13: 330 | M13: 332 | N13: =+SUM(K13:M13) -> 991 | O13: 329 | P13: 331 | Q13: 330 | R13: =+SUM(O13:Q13) -> 990 | S13: =+F13+J13+N13+R13 -> 3970 | T13: 329 | U13: 332 | V13: 332 | W13: =+SUM(T13:V13) -> 993 | X13: 331 | Y13: 328 | Z13: 330 | AA13: =+SUM(X13:Z13) -> 989 | AE13: =+SUM(AB13:AD13) -> 0 | AI13: =+SUM(AF13:AH13) -> 0 | AJ13: =+W13+AA13+AE13+AI13 -> 1982
B14: Elektros energijos sąnaudos | C14: 30 | D14: 33 | E14: 35 | F14: =+SUM(C14:E14) -> 98 | G14: 33 | H14: 31 | I14: 33 | J14: =+SUM(G14:I14) -> 97 | K14: 29 | L14: 33 | M14: 36 | N14: =+SUM(K14:M14) -> 98 | O14: 33 | P14: 37 | Q14: 30 | R14: =+SUM(O14:Q14) -> 100 | S14: =+F14+J14+N14+R14 -> 393 | T14: 35 | U14: 30 | V14: 33 | W14: =+SUM(T14:V14) -> 98 | X14: 32 | Y14: 35 | Z14: 33 | AA14: =+SUM(X14:Z14) -> 100 | AE14: =+SUM(AB14:AD14) -> 0 | AI14: =+SUM(AF14:AH14) -> 0 | AJ14: =+W14+AA14+AE14+AI14 -> 198
B15: Darbo užmokestis | C15: 1330 | D15: 1316 | E15: 1328 | F15: =+SUM(C15:E15) -> 3974 | G15: 1328 | H15: 1316 | I15: 1336 | J15: =+SUM(G15:I15) -> 3980 | K15: 1314 | L15: 1318 | M15: 1326 | N15: =+SUM(K15:M15) -> 3958 | O15: 1316 | P15: 1324 | Q15: 1318 | R15: =+SUM(O15:Q15) -> 3958 | S15: =+F15+J15+N15+R15 -> 15870 | T15: 1316 | U15: 1326 | V15: 1326 | W15: =+SUM(T15:V15) -> 3968 | X15: 1324 | Y15: 1312 | Z15: 1318 | AA15: =+SUM(X15:Z15) -> 3954 | AE15: =+SUM(AB15:AD15) -> 0 | AI15: =+SUM(AF15:AH15) -> 0 | AJ15: =+W15+AA15+AE15+AI15 -> 7922
B16: VISOS IŠLAIDOS | C16: =+SUBTOTAL(9,C11:C15) -> 5683 | D16: =+SUBTOTAL(9,D11:D15) -> 5624 | E16: =+SUBTOTAL(9,E11:E15) -> 5681 | F16: =+SUBTOTAL(9,F11:F15) -> 16988 | G16: =+SUBTOTAL(9,G11:G15) -> 5677 | H16: =+SUBTOTAL(9,H11:H15) -> 5622 | I16: =+SUBTOTAL(9,I11:I15) -> 5711 | J16: =+SUBTOTAL(9,J11:J15) -> 17010 | ... AJ16: =+SUBTOTAL(9,AJ11:AJ15) -> 33871
B17: BALANSAS | C17: =+C10-C16 -> 7616 | D17: =+D10-D16 -> 7528 | E17: =+E10-E16 -> 7608 | F17: =+F10-F16 -> 22752 | G17: =+G10-G16 -> 7604 | H17: =+H10-H16 -> 7529 | I17: =+I10-I16 -> 7647 | J17: =+J10-J16 -> 22779 | ... AJ17: =+AJ10-AJ16 -> 45358

Sheet U9
A1: U9 | B1: Duomenų teisingumo tikrinimas (Data Validation), sąrašų sudarymas;
B3: 1. | C3: Naudodamiesi DATA VALIDATION DUOMENŲ TIKRINIMO įrankiu apribokite įvedimą geltoname langelyje tik skaičiams nuo 10 iki 25
B7: 2. | C7: Naudodamiesi DATA VALIDATION DUOMENŲ TIKRINIMO įrankiu apribokite įvedimą geltoname langelyje tik tekstui nuo 5 iki 10 simbolių
E9: length
B11: 3. | C11: Naudodamiesi DATA VALIDATION DUOMENŲ TIKRINIMO įrankiu pažymėkite reikšmes <40
C13: 20 | D13: 25 | E13: 31 | F13: 46 | H13: circle invalid data
C14: =+C13+14 -> 34 | D14: =+D13+14 -> 39 | E14: =+E13+14 -> 45 | F14: =+F13+14 -> 60
C15: =+C14-7 -> 27 | D15: =+D14-7 -> 32 | E15: =+E14-7 -> 38 | F15: =+F14-7 -> 53
C16: =+C14/2+C15 -> 44 | D16: =+D14/2+D15 -> 51.5 | E16: =+E14/2+E15 -> 60.5 | F16: =+F14/2+F15 -> 83
B18: 4. | C18: Naudodamiesi DATA VALIDATION DUOMENŲ TIKRINIMO įrankiu sudarykite unikalų pasirinkties sąrašą
B20: Rokiškio naminis pienas | D20: Smetoniškas sviestas
B21: Dvaro varškė
B22: Smetoniškas sviestas
B23: Rokiškio naminis pienas
B24: Dvaro varškė
B25: Dvaro varškė
B26: Dvaro varškė
B27: Dvaro varškė
B28: Rūkytas lydytas sūris "Visiems"
B29: Grietinė "Žaloji karvutė"
B30: Rokiškio naminis pienas
B31: Smetoniškas sviestas
B32: Rokiškio naminis pienas
... B102: Smetoniškas sviestas
C106: 5. | D106: Nustatykite sudėtingus duomenų tikrinimo apribojimus, naudojant CUSTOM PASIRINKTINĮ duomenų tikrinimo būdą (įrašant funkcijas)
C108: 1. Leisti įvesti tik skaičių, mažesnį nei 5000 | H108: 4999 | I108: =AND(ISNUMBER(H108),H108<5000) -> TRUE | J108: Formulė: | K108: =_xlfn.FORMULATEXT(I108) -> =AND(ISNUMBER(H108),H108<5000)
C109: 2. Leisti įvesti tik tekstą | H109: MAMA | I109: =ISTEXT(H109) -> TRUE | J109: Formulė: | K109: =_xlfn.FORMULATEXT(I109) -> =ISTEXT(H109)
C110: 3. Leisti įvesti tekstą, kuris prasideda "AA-" | H110: AA- | I110: =EXACT(LEFT(H110,3),"AA-") -> TRUE | J110: Formulė: | K110: =_xlfn.FORMULATEXT(I110) -> =EXACT(LEFT(H110,3),"AA-")
C111: 4. Leisti įvesti rausvame diapazone tik unikalius įrašus | H111: 0 | I111: =COUNTIF($H$111:$H111,H111)<=1 -> TRUE | J111: Formulė: | K111: =_xlfn.FORMULATEXT(I111) -> =COUNTIF($H$111:$H111,H111)<=1

Sheet U10
A1: U10 | B1: Laiko ir datos funkcijos, veiksmai su jomis;
A3: 1. Data – tai skaičius datos formatu
B5: 45155
A9: 2. Darbas su šiandienos data
B10: Šiandienos data: TODAY() ir CTRL+; | D10: =TODAY() -> 45999 | E10: 45165
B11: Laikas dabar NOW() ir CTRL+SHIFT+: | D11: =NOW() -> 45999.446
B12: =NOW() -> 45999.446
B15: Funkcijos TODAY() pritaikymas, naudojant sąlyginį formatavimą formulėmis
B16: =TODAY() -> 45999
D17: =+TODAY() -> 45999
B19: Klientas | C19: Paslaugos data | D19: Atsiskaitymo data | F19: Atsiskaitymas
B20: UAB "Miesto vandenys" | C20: =+TODAY()-25 -> 45974 | D20: =+C20+20 -> 45994 | F20: Atsiskaitė
B21: UAB "Senieji kaimo stogai" | C21: =+C20+2 -> 45976 | D21: =+C21+20 -> 45996 | F21: Atsiskaitė
B22: UAB "Būk apsiavęs" | C22: =+C21+2 -> 45978 | D22: =+C22+20 -> 45998 | F22: Neatsiskaitė
B23: UAB "Miesto švara" | C23: =+C22+2 -> 45980 | D23: =+C23+20 -> 46000 | F23: Neatsiskaitė
B24: UAB "Želdiniai" | C24: =+C23+2 -> 45982 | D24: =+C24+20 -> 46002 | F24: Neatsiskaitė
A27: 3. Datos suskaldymas/sujungimas | C27: 43682 | F27: 0.094270833
B29: YEAR() | C29: =YEAR(C27) -> 2019 | E29: HOUR() | F29: =HOUR(F27) -> 2
B30: MONTH() | C30: =MONTH(C27) -> 8 | E30: MINUTE() | F30: =MINUTE(F27) -> 15
B31: DAY() | C31: =DAY(C27) -> 5 | E31: SECOND() | F31: =SECOND(F27) -> 45
B33: DATE() | C33: =DATE(C29,C30,C31) -> 43682 | E33: TIME() | F33: =TIME(F29,F30,F31) -> 0.094270833
A35: 4. Datos elementų šablonai (TEXT())
B37: Susirinkimas skelbiamas | E37: YYYY | F37: 2019 | H37: MMMM | I37: rugpjūtis | K37: DDDD | L37: pirmadienis
E38: YYY | F38: 2019 | H38: MMM | I38: rugp | K38: DDD | L38: pr
B39: =B37&" "&TEXT(C33,"mmmm dd, (dddd)") -> Susirinkimas skelbiamas August 05, (Monday) | E39: YY | F39: 19 | H39: MM | I39: 08 | K39: DD | L39: 05
E40: Y | F40: 19 | H40: M | I40: 8 | K40: D | L40: 5
A42: 5. Dienų skaičiaus skaičiavimai
N43: Holidays
B44: DAYS() | D44: Apskaičiuoti dienų skaičių tarp 2-jų datų | G44: 43466 | I44: 43703 | K44: =_xlfn.DAYS(I44,G44) -> 237 | N44: 43466
B45: NETWORKDAYS(), NETWORKDAYS.INTL() | D45: Apskaičiuoti darbo dienų skaičių tarp 2-jų datų | G45: 43466 | I45: 43703 | K45: =NETWORKDAYS(G45,I45,N44:N58) -> 164 | N45: 43512
G46: 43466 | I46: 43703 | K46: =NETWORKDAYS.INTL(G46,I46) -> 170 | N46: 43535
B47: WORKDAY(), WORKDAY.INTL() | D47: Apskaičiuoti datą po tam tikro darbo dienų skaičiaus | G47: 43466 | I47: 50 | K47: =WORKDAY(G47,I47) -> 43536 | N47: 43576
G48: 43466 | I48: 50 | K48: =WORKDAY.INTL(G48,I48) -> 43536 | N48: 43577
N49: 43586
A50: 6. Savaitės dienos eilės numeris | N50: 43590
N51: 43618
B52: WEEKDAY() | G52: 43466 | I52: Lietuvoje | K52: =WEEKDAY(G52,2) -> 2 | N52: 43640
I53: Amerikoje | K53: =WEEKDAY(G52,1) -> 3 | N53: 43652
N54: 43692
A55: 7. Mėnesio dienos paskaičiavimai | N55: 43770
...

Sheet U11
A1: U11 | B1: Darbas su vardinėmis lentelėmis (TABLES);
B4: Data | C4: Prekės pavadinimas | D4: Tiekėjas | E4: Kiekis, vnt. | F4: Kaina, Eur | G4: Suma | H4: Procentas
B5: 42736 | C5: Rokiškio naminis pienas | D5: Rokiškio pienas | E5: 20 | F5: 1.55 | G5: ='U11'!$E5*'U11'!$F5 -> 31 | H5: ='U11'!$G5/SUM('U11'!$G$5:$G$27) -> 0.053343428
B6: 42737 | C6: Dvaro varškė | D6: Pieno žvaigždės | E6: 20 | F6: 2.12 | G6: ='U11'!$E6*'U11'!$F6 -> 42.4 | H6: ='U11'!$G6/SUM('U11'!$G$5:$G$27) -> 0.072960044
B7: 42738 | C7: Smetoniškas sviestas | D7: Pieno žvaigždės | E7: 9 | F7: 2.02 | G7: ='U11'!$E7*'U11'!$F7 -> 18.18 | H7: ='U11'!$G7/SUM('U11'!$G$5:$G$27) -> 0.03128334
B8: 42739 | C8: Rokiškio naminis pienas | D8: Rokiškio pienas | E8: 24 | F8: 1.55 | G8: ='U11'!$E8*'U11'!$F8 -> 37.2 | H8: ='U11'!$G8/SUM('U11'!$G$5:$G$27) -> 0.064012114
B9: 42742 | C9: Dvaro varškė | D9: Pieno žvaigždės | E9: 15 | F9: 2.12 | G9: ='U11'!$E9*'U11'!$F9 -> 31.8 | H9: ='U11'!$G9/SUM('U11'!$G$5:$G$27) -> 0.054720033
B10: 42743 | C10: Dvaro varškė | D10: Pieno žvaigždės | E10: 21 | F10: 2.12 | G10: ='U11'!$E10*'U11'!$F10 -> 44.52 | H10: ='U11'!$G10/SUM('U11'!$G$5:$G$27) -> 0.076608046
B11: 42744 | C11: Dvaro varškė | D11: Pieno žvaigždės | E11: 8 | F11: 2.12 | G11: ='U11'!$E11*'U11'!$F11 -> 16.96 | H11: ='U11'!$G11/SUM('U11'!$G$5:$G$27) -> 0.029184018
B12: 42745 | C12: Dvaro varškė | D12: Pieno žvaigždės | E12: 10 | F12: 2.12 | G12: ='U11'!$E12*'U11'!$F12 -> 21.2 | H12: ='U11'!$G12/SUM('U11'!$G$5:$G$27) -> 0.036480022
B13: 42746 | C13: Rūkytas lydytas sūris "Visiems" | D13: Rokiškio pienas | E13: 15 | F13: 1.4 | G13: ='U11'!$E13*'U11'!$F13 -> 21 | H13: ='U11'!$G13/SUM('U11'!$G$5:$G$27) -> 0.036135871
B14: 42749 | C14: Grietinė "Žaloji karvutė" | D14: Rokiškio pienas | E14: 9 | F14: 1.09 | G14: ='U11'!$E14*'U11'!$F14 -> 9.81 | H14: ='U11'!$G14/SUM('U11'!$G$5:$G$27) -> 0.016880614
B15: 42750 | C15: Rokiškio naminis pienas | D15: Rokiškio pienas | E15: 23 | F15: 1.55 | G15: ='U11'!$E15*'U11'!$F15 -> 35.65 | H15: ='U11'!$G15/SUM('U11'!$G$5:$G$27) -> 0.061344943
B16: 42751 | C16: Smetoniškas sviestas | D16: Pieno žvaigždės | E16: 15 | F16: 2.02 | G16: ='U11'!$E16*'U11'!$F16 -> 30.3 | H16: ='U11'!$G16/SUM('U11'!$G$5:$G$27) -> 0.052138899
... B24: 42763 | C24: Rokiškio naminis pienas | D24: Rokiškio pienas | E24: 20 | F24: 1.55 | G24: ='U11'!$E24*'U11'!$F24 -> 31 | H24: ='U11'!$G24/SUM('U11'!$G$5:$G$27) -> 0.053343428
B25: 42764 | C25: Dvaro varškė | D25: Pieno žvaigždės | E25: 8 | F25: 2.12 | G25: ='U11'!$E25*'U11'!$F25 -> 16.96 | H25: ='U11'!$G25/SUM('U11'!$G$5:$G$27) -> 0.029184018 | L25: Santykinė nuoroda | N25: Absoliuti nuoroda
B26: 42765 | C26: Grietinė "Žaloji karvutė" | D26: Rokiškio pienas | E26: 17 | F26: 1.09 | G26: ='U11'!$E26*'U11'!$F26 -> 18.53 | H26: ='U11'!$G26/SUM('U11'!$G$5:$G$27) -> 0.031885604 | K26: Stulpeliui | L26: =Table1[column1] | N26: =Table1[[column1]:[column1]]
B27: 42766 | C27: Rokiškio naminis pienas | D27: Rokiškio pienas | E27: 7 | F27: 1.55 | G27: ='U11'!$E27*'U11'!$F27 -> 10.85 | H27: ='U11'!$G27/SUM('U11'!$G$5:$G$27) -> 0.0186702 | K27: Langeliui | L27: =Table1[@[column1]] | N27: =Table1[@[column1]:[column1]]
B28: Total | E28: =SUBTOTAL(103,tblpienotiekejai[Kiekis, vnt.]) -> 23 | F28: =SUBTOTAL(104,tblpienotiekejai[Kaina, Eur]) -> 2.12 | G28: =SUBTOTAL(109,tblpienotiekejai[Suma]) -> 581.14 | H28: =SUBTOTAL(109,tblpienotiekejai[Procentas]) -> 1

Sheet U12
A1: U12 | B1: Sąlyginės (loginės) funkcijos (IF, AND, OR, SUMIF(S), COUNTIF(S), AVERAGEIF(S)), funkcija funkcijoje;
B3: 1. Skaičiui geltoname langelyje pritaikykime funkciją IF, kad matytume, ar tas skaičius yra < 5, ar >= 5. Po to antrąjį teiginį išplėskite į dar du galimus teiginius: >5, =5.
B6: 6 | D6: =IF(B6<5,"maziau nei 5", "daugiau nei 5") -> daugiau nei 5
B8: 2. Panaudodami logines funkcijas IF, AND, OR parašykite formulę, kuria apskaičiuotumėte nuolaidos dydį. Nuolaidos taikymo sąlygos:
C9: 1. Jei pirkėjas nuperka už 10 eur ir daugiau, taikoma 5% nuolaida
C10: 2. Jei pirkėjas turi nuolaidų kortelę, taikoma 5% nuolaida | J10: Data validation:
C11: 3. Jei pirkėjas turi nuolaidų kortelę ir nuperka už 10 eur ir daugiau, taikoma 8% nuolaida
J12: Lojalumo kortele | K12: Taip
B13: IF: | C13: =IF(AND(K12="Taip",K13>=10,K14),IF(OR(K12="Taip",K13>=10),K15,K16)) -> 0.05 | J13: Sumos dydis | K13: 12
J14: Abu kriterijai | K14: 0.08
B15: 3. Už kokią sumą "Pieno žvaigždės" pardavė produkcijos ir kiek išrašyta sąskaitų (SUMIF, COUNTIF) | J15: Vienas kriterijus | K15: 0.05
J16: Nei vienas kriterijus | K16: 0
B17: Data | C17: Tiekėjas | D17: Kiekis, vnt. | E17: Kaina, Eur | F17: Suma, Eur | H17: List:
B18: 42736 | C18: Rokiškio pienas | D18: 20 | E18: 1.55 | F18: =D18*E18 -> 31 | H18: Rokiškio pienas | I18: ? PADEDA PATIKrinti ar yra klaidu
B19: 42737 | C19: Pieno žvaigždės | D19: 20 | E19: 2.12 | F19: =D19*E19 -> 42.4 | H19: Vienam Kriterijui:
A20: 42745 | B20: 42738 | C20: Pieno žvaigždės | D20: 9 | E20: 2.02 | F20: =D20*E20 -> 18.18 | G20: Suma: | H20: =SUMIF(C18:C40,H18,F18:F40) -> 346.7 | I20: ieskome c eilutej h reiskme ir rezultatas yra suma
B21: 42739 | C21: Rokiškio pienas | D21: 24 | E21: 1.55 | F21: =D21*E21 -> 37.2 | G21: Vidurkis: | H21: =AVERAGEIF(C18:C40,H18,F18:F40) -> 24.764286
B22: 42742 | C22: Pieno žvaigždės | D22: 15 | E22: 2.12 | F22: =D22*E22 -> 31.8 | G22: Kiekis: | H22: =COUNTIF(C18:C40,H18) -> 14
B23: 42743 | C23: Pieno žvaigždės | D23: 21 | E23: 2.12 | F23: =D23*E23 -> 44.52
B24: 42744 | C24: Pieno žvaigždės | D24: 8 | E24: 2.12 | F24: =D24*E24 -> 16.96 | H24: Daugiau Kriteriju:
B25: 42745 | C25: Pieno žvaigždės | D25: 10 | E25: 2.12 | F25: =D25*E25 -> 21.2
B26: 42746 | C26: Rokiškio pienas | D26: 15 | E26: 1.4 | F26: =D26*E26 -> 21 | G26: Suma: | H26: =SUMIFS($F$18:$F$40,$C$18:$C$40,$H$18,$B$18:$B$40,"<=10/01/2017") -> 68.2
